<sdf version='1.7'>
  <world name='default'>
    <model name='ground_plane'>
      <static>1</static>
      <link name='link'>
        <collision name='collision'>
          <geometry>
            <plane>
              <normal>0 0 1</normal>
              <size>100 100</size>
            </plane>
          </geometry>
          <surface>
            <contact>
              <collide_bitmask>65535</collide_bitmask>
              <ode/>
            </contact>
            <friction>
              <ode>
                <mu>100</mu>
                <mu2>50</mu2>
              </ode>
              <torsional>
                <ode/>
              </torsional>
            </friction>
            <bounce/>
          </surface>
          <max_contacts>10</max_contacts>
        </collision>
        <visual name='visual'>
          <cast_shadows>0</cast_shadows>
          <geometry>
            <plane>
              <normal>0 0 1</normal>
              <size>100 100</size>
            </plane>
          </geometry>
          <material>
            <script>
              <uri>file://media/materials/scripts/gazebo.material</uri>
              <name>Gazebo/Grey</name>
            </script>
          </material>
        </visual>
        <self_collide>0</self_collide>
        <enable_wind>0</enable_wind>
        <kinematic>0</kinematic>
      </link>
    </model>
    
    <gravity>0 0 -9.8</gravity>
    <magnetic_field>6e-06 2.3e-05 -4.2e-05</magnetic_field>
    <atmosphere type='adiabatic'/>
    <physics type='ode'>
      <max_step_size>0.001</max_step_size>
      <real_time_factor>1</real_time_factor>
      <real_time_update_rate>1000</real_time_update_rate>
    </physics>
    <scene>
      <ambient>0.4 0.4 0.4 1</ambient>
      <background>0.7 0.7 0.7 1</background>
      <shadows>1</shadows>
    </scene>
    <audio>
      <device>default</device>
    </audio>
    <wind/>
    <spherical_coordinates>
      <surface_model>EARTH_WGS84</surface_model>
      <latitude_deg>0</latitude_deg>
      <longitude_deg>0</longitude_deg>
      <elevation>0</elevation>
      <heading_deg>0</heading_deg>
    </spherical_coordinates>
    
    <state world_name='default'>
      <sim_time>649 135000000</sim_time>
      <real_time>110 147409148</real_time>
      <wall_time>1668436828 973225494</wall_time>
      <iterations>108489</iterations>
    </state>
    
    <model name="single_joint">
  <gazebo reference="base">
    <material>Gazebo/GrassFloor</material>
  </gazebo>
  <link name="world"/>
  <joint name="link_joint" type="continuous">
    <axis xyz="0 0 1"/>
    <parent link="world"/>
    <origin rpy="0 0 0" xyz="0 0 1"/>
    <child link="link"/>
    <limit effort="100" velocity="100" k_velocity="0" />
    <joint_properties damping="0.1" friction="1.0" />
  </joint>
  <link name="link">
    <inertial>
      <mass value="10"/>
      <origin xyz="0 0 0"/>
      <inertia ixx="1.0" ixy="0.0" ixz="0.0" iyy="0.1" iyz="0.0" izz="0.1"/>
    </inertial>
    <visual>
      <origin rpy="0 0 1" xyz="0 0 0"/>
      <geometry>
        <box size="0.2 1.0 0.2"/>
      </geometry>
    </visual>
    <collision>
      <origin rpy="0 0 1" xyz="0 0 0"/>
      <geometry>
        <box size="0.2 1.0 0.2"/>
      </geometry>
    </collision>
  </link>
  <gazebo reference="link">
    <material>Gazebo/GrassFloor</material>
    <turnGravityOff>true</turnGravityOff>
  </gazebo>
  
   <gazebo>
    <controller:gazebo_ros_force name="gazebo_ros_force" plugin="libgazebo_ros_force.so">
      <alwaysOn>true</alwaysOn>
      <update>100</update>
      <updateRate>100.0</updateRate>
      <bodyName>link</bodyName>
      <topicName>force</topicName>
    </controller:gazebo_ros_force>
  </gazebo>
</model>
    
    <gui fullscreen='0'>
      <camera name='user_camera'>
        <pose>-1.36897 -1.69666 1.26336 0 0.405795 0.677009</pose>
        <view_controller>orbit</view_controller>
        <projection_type>perspective</projection_type>
      </camera>
    </gui>
  </world>
</sdf>
